INFO:werkzeug:[31m[1mWARNING: This is a development server. Do not use it in a production deployment. Use a production WSGI server instead.[0m
 * Running on all addresses (0.0.0.0)
 * Running on http://127.0.0.1:5000
 * Running on http://192.168.1.207:5000
INFO:werkzeug:[33mPress CTRL+C to quit[0m
INFO:httpx:HTTP Request: POST https://api.telegram.org/bot7818122772:AAEYZgEmdLxrNWpBHchD84vuhsbQ9JMnUgE/getMe "HTTP/1.1 200 OK"
INFO:httpx:HTTP Request: POST https://api.telegram.org/bot7818122772:AAEYZgEmdLxrNWpBHchD84vuhsbQ9JMnUgE/deleteWebhook "HTTP/1.1 200 OK"
INFO:telegram.ext.Application:Application started
INFO:werkzeug:127.0.0.1 - - [19/Mar/2025 16:53:13] "GET / HTTP/1.1" 200 -
INFO:werkzeug:127.0.0.1 - - [19/Mar/2025 16:53:13] "GET /get_ips HTTP/1.1" 200 -
INFO:httpx:HTTP Request: POST https://api.telegram.org/bot7818122772:AAEYZgEmdLxrNWpBHchD84vuhsbQ9JMnUgE/getUpdates "HTTP/1.1 409 Conflict"
ERROR:telegram.ext.Application:No error handlers are registered, logging exception.
Traceback (most recent call last):
  File "/Users/gulmaral/Desktop/informatics/face_chat_app/venv/lib/python3.13/site-packages/telegram/ext/_utils/networkloop.py", line 115, in network_retry_loop
    if not await do_action():
           ^^^^^^^^^^^^^^^^^
  File "/Users/gulmaral/Desktop/informatics/face_chat_app/venv/lib/python3.13/site-packages/telegram/ext/_utils/networkloop.py", line 108, in do_action
    return action_cb_task.result()
           ~~~~~~~~~~~~~~~~~~~~~^^
  File "/Users/gulmaral/Desktop/informatics/face_chat_app/venv/lib/python3.13/site-packages/telegram/ext/_updater.py", line 376, in polling_action_cb
    updates = await self.bot.get_updates(
              ^^^^^^^^^^^^^^^^^^^^^^^^^^^
    ...<7 lines>...
    )
    ^
  File "/Users/gulmaral/Desktop/informatics/face_chat_app/venv/lib/python3.13/site-packages/telegram/ext/_extbot.py", line 658, in get_updates
    updates = await super().get_updates(
              ^^^^^^^^^^^^^^^^^^^^^^^^^^
    ...<9 lines>...
    )
    ^
  File "/Users/gulmaral/Desktop/informatics/face_chat_app/venv/lib/python3.13/site-packages/telegram/_bot.py", line 4605, in get_updates
    await self._post(
    ^^^^^^^^^^^^^^^^^
    ...<7 lines>...
    ),
    ^
  File "/Users/gulmaral/Desktop/informatics/face_chat_app/venv/lib/python3.13/site-packages/telegram/_bot.py", line 691, in _post
    return await self._do_post(
           ^^^^^^^^^^^^^^^^^^^^
    ...<6 lines>...
    )
    ^
  File "/Users/gulmaral/Desktop/informatics/face_chat_app/venv/lib/python3.13/site-packages/telegram/ext/_extbot.py", line 362, in _do_post
    return await super()._do_post(
           ^^^^^^^^^^^^^^^^^^^^^^^
    ...<6 lines>...
    )
    ^
  File "/Users/gulmaral/Desktop/informatics/face_chat_app/venv/lib/python3.13/site-packages/telegram/_bot.py", line 720, in _do_post
    result = await request.post(
             ^^^^^^^^^^^^^^^^^^^
    ...<6 lines>...
    )
    ^
  File "/Users/gulmaral/Desktop/informatics/face_chat_app/venv/lib/python3.13/site-packages/telegram/request/_baserequest.py", line 202, in post
    result = await self._request_wrapper(
             ^^^^^^^^^^^^^^^^^^^^^^^^^^^^
    ...<7 lines>...
    )
    ^
  File "/Users/gulmaral/Desktop/informatics/face_chat_app/venv/lib/python3.13/site-packages/telegram/request/_baserequest.py", line 385, in _request_wrapper
    raise Conflict(message)
telegram.error.Conflict: Conflict: terminated by other getUpdates request; make sure that only one bot instance is running
INFO:werkzeug:127.0.0.1 - - [19/Mar/2025 16:53:15] "GET / HTTP/1.1" 200 -
INFO:werkzeug:127.0.0.1 - - [19/Mar/2025 16:53:15] "GET /get_ips HTTP/1.1" 200 -
INFO:werkzeug:127.0.0.1 - - [19/Mar/2025 16:53:16] "GET / HTTP/1.1" 200 -
INFO:werkzeug:127.0.0.1 - - [19/Mar/2025 16:53:16] "GET /get_ips HTTP/1.1" 200 -
INFO:werkzeug:127.0.0.1 - - [19/Mar/2025 16:53:16] "GET / HTTP/1.1" 200 -
INFO:werkzeug:127.0.0.1 - - [19/Mar/2025 16:53:16] "GET /get_ips HTTP/1.1" 200 -
INFO:werkzeug:127.0.0.1 - - [19/Mar/2025 16:53:16] "GET / HTTP/1.1" 200 -
INFO:werkzeug:127.0.0.1 - - [19/Mar/2025 16:53:16] "GET /get_ips HTTP/1.1" 200 -
INFO:root:[DDoS] IP 127.0.0.1 –∑–∞–±–ª–æ–∫–∏—Ä–æ–≤–∞–Ω –∑–∞ –ø—Ä–µ–≤—ã—à–µ–Ω–∏–µ –ª–∏–º–∏—Ç–∞ –∑–∞–ø—Ä–æ—Å–æ–≤.
INFO:werkzeug:127.0.0.1 - - [19/Mar/2025 16:53:16] "[31m[1mGET / HTTP/1.1[0m" 403 -
INFO:werkzeug:127.0.0.1 - - [19/Mar/2025 16:53:17] "[31m[1mGET / HTTP/1.1[0m" 403 -
INFO:werkzeug:127.0.0.1 - - [19/Mar/2025 16:53:17] "[31m[1mGET / HTTP/1.1[0m" 403 -
INFO:werkzeug:127.0.0.1 - - [19/Mar/2025 16:53:20] "[31m[1mGET / HTTP/1.1[0m" 403 -
INFO:werkzeug:127.0.0.1 - - [19/Mar/2025 16:53:20] "[31m[1mGET / HTTP/1.1[0m" 403 -
INFO:werkzeug:127.0.0.1 - - [19/Mar/2025 16:53:20] "[31m[1mGET / HTTP/1.1[0m" 403 -
INFO:httpx:HTTP Request: POST https://api.telegram.org/bot7818122772:AAEYZgEmdLxrNWpBHchD84vuhsbQ9JMnUgE/getUpdates "HTTP/1.1 409 Conflict"
ERROR:telegram.ext.Application:No error handlers are registered, logging exception.
Traceback (most recent call last):
  File "/Users/gulmaral/Desktop/informatics/face_chat_app/venv/lib/python3.13/site-packages/telegram/ext/_utils/networkloop.py", line 115, in network_retry_loop
    if not await do_action():
           ^^^^^^^^^^^^^^^^^
  File "/Users/gulmaral/Desktop/informatics/face_chat_app/venv/lib/python3.13/site-packages/telegram/ext/_utils/networkloop.py", line 108, in do_action
    return action_cb_task.result()
           ~~~~~~~~~~~~~~~~~~~~~^^
  File "/Users/gulmaral/Desktop/informatics/face_chat_app/venv/lib/python3.13/site-packages/telegram/ext/_updater.py", line 376, in polling_action_cb
    updates = await self.bot.get_updates(
              ^^^^^^^^^^^^^^^^^^^^^^^^^^^
    ...<7 lines>...
    )
    ^
  File "/Users/gulmaral/Desktop/informatics/face_chat_app/venv/lib/python3.13/site-packages/telegram/ext/_extbot.py", line 658, in get_updates
    updates = await super().get_updates(
              ^^^^^^^^^^^^^^^^^^^^^^^^^^
    ...<9 lines>...
    )
    ^
  File "/Users/gulmaral/Desktop/informatics/face_chat_app/venv/lib/python3.13/site-packages/telegram/_bot.py", line 4605, in get_updates
    await self._post(
    ^^^^^^^^^^^^^^^^^
    ...<7 lines>...
    ),
    ^
  File "/Users/gulmaral/Desktop/informatics/face_chat_app/venv/lib/python3.13/site-packages/telegram/_bot.py", line 691, in _post
    return await self._do_post(
           ^^^^^^^^^^^^^^^^^^^^
    ...<6 lines>...
    )
    ^
  File "/Users/gulmaral/Desktop/informatics/face_chat_app/venv/lib/python3.13/site-packages/telegram/ext/_extbot.py", line 362, in _do_post
    return await super()._do_post(
           ^^^^^^^^^^^^^^^^^^^^^^^
    ...<6 lines>...
    )
    ^
  File "/Users/gulmaral/Desktop/informatics/face_chat_app/venv/lib/python3.13/site-packages/telegram/_bot.py", line 720, in _do_post
    result = await request.post(
             ^^^^^^^^^^^^^^^^^^^
    ...<6 lines>...
    )
    ^
  File "/Users/gulmaral/Desktop/informatics/face_chat_app/venv/lib/python3.13/site-packages/telegram/request/_baserequest.py", line 202, in post
    result = await self._request_wrapper(
             ^^^^^^^^^^^^^^^^^^^^^^^^^^^^
    ...<7 lines>...
    )
    ^
  File "/Users/gulmaral/Desktop/informatics/face_chat_app/venv/lib/python3.13/site-packages/telegram/request/_baserequest.py", line 385, in _request_wrapper
    raise Conflict(message)
telegram.error.Conflict: Conflict: terminated by other getUpdates request; make sure that only one bot instance is running
INFO:httpx:HTTP Request: POST https://api.telegram.org/bot7818122772:AAEYZgEmdLxrNWpBHchD84vuhsbQ9JMnUgE/getUpdates "HTTP/1.1 200 OK"
INFO:httpx:HTTP Request: POST https://api.telegram.org/bot7818122772:AAEYZgEmdLxrNWpBHchD84vuhsbQ9JMnUgE/sendMessage "HTTP/1.1 200 OK"
INFO:httpx:HTTP Request: POST https://api.telegram.org/bot7818122772:AAEYZgEmdLxrNWpBHchD84vuhsbQ9JMnUgE/getUpdates "HTTP/1.1 409 Conflict"
ERROR:telegram.ext.Application:No error handlers are registered, logging exception.
Traceback (most recent call last):
  File "/Users/gulmaral/Desktop/informatics/face_chat_app/venv/lib/python3.13/site-packages/telegram/ext/_utils/networkloop.py", line 115, in network_retry_loop
    if not await do_action():
           ^^^^^^^^^^^^^^^^^
  File "/Users/gulmaral/Desktop/informatics/face_chat_app/venv/lib/python3.13/site-packages/telegram/ext/_utils/networkloop.py", line 108, in do_action
    return action_cb_task.result()
           ~~~~~~~~~~~~~~~~~~~~~^^
  File "/Users/gulmaral/Desktop/informatics/face_chat_app/venv/lib/python3.13/site-packages/telegram/ext/_updater.py", line 376, in polling_action_cb
    updates = await self.bot.get_updates(
              ^^^^^^^^^^^^^^^^^^^^^^^^^^^
    ...<7 lines>...
    )
    ^
  File "/Users/gulmaral/Desktop/informatics/face_chat_app/venv/lib/python3.13/site-packages/telegram/ext/_extbot.py", line 658, in get_updates
    updates = await super().get_updates(
              ^^^^^^^^^^^^^^^^^^^^^^^^^^
    ...<9 lines>...
    )
    ^
  File "/Users/gulmaral/Desktop/informatics/face_chat_app/venv/lib/python3.13/site-packages/telegram/_bot.py", line 4605, in get_updates
    await self._post(
    ^^^^^^^^^^^^^^^^^
    ...<7 lines>...
    ),
    ^
  File "/Users/gulmaral/Desktop/informatics/face_chat_app/venv/lib/python3.13/site-packages/telegram/_bot.py", line 691, in _post
    return await self._do_post(
           ^^^^^^^^^^^^^^^^^^^^
    ...<6 lines>...
    )
    ^
  File "/Users/gulmaral/Desktop/informatics/face_chat_app/venv/lib/python3.13/site-packages/telegram/ext/_extbot.py", line 362, in _do_post
    return await super()._do_post(
           ^^^^^^^^^^^^^^^^^^^^^^^
    ...<6 lines>...
    )
    ^
  File "/Users/gulmaral/Desktop/informatics/face_chat_app/venv/lib/python3.13/site-packages/telegram/_bot.py", line 720, in _do_post
    result = await request.post(
             ^^^^^^^^^^^^^^^^^^^
    ...<6 lines>...
    )
    ^
  File "/Users/gulmaral/Desktop/informatics/face_chat_app/venv/lib/python3.13/site-packages/telegram/request/_baserequest.py", line 202, in post
    result = await self._request_wrapper(
             ^^^^^^^^^^^^^^^^^^^^^^^^^^^^
    ...<7 lines>...
    )
    ^
  File "/Users/gulmaral/Desktop/informatics/face_chat_app/venv/lib/python3.13/site-packages/telegram/request/_baserequest.py", line 385, in _request_wrapper
    raise Conflict(message)
telegram.error.Conflict: Conflict: terminated by other getUpdates request; make sure that only one bot instance is running
INFO:httpx:HTTP Request: POST https://api.telegram.org/bot7818122772:AAEYZgEmdLxrNWpBHchD84vuhsbQ9JMnUgE/getUpdates "HTTP/1.1 409 Conflict"
ERROR:telegram.ext.Application:No error handlers are registered, logging exception.
Traceback (most recent call last):
  File "/Users/gulmaral/Desktop/informatics/face_chat_app/venv/lib/python3.13/site-packages/telegram/ext/_utils/networkloop.py", line 115, in network_retry_loop
    if not await do_action():
           ^^^^^^^^^^^^^^^^^
  File "/Users/gulmaral/Desktop/informatics/face_chat_app/venv/lib/python3.13/site-packages/telegram/ext/_utils/networkloop.py", line 108, in do_action
    return action_cb_task.result()
           ~~~~~~~~~~~~~~~~~~~~~^^
  File "/Users/gulmaral/Desktop/informatics/face_chat_app/venv/lib/python3.13/site-packages/telegram/ext/_updater.py", line 376, in polling_action_cb
    updates = await self.bot.get_updates(
              ^^^^^^^^^^^^^^^^^^^^^^^^^^^
    ...<7 lines>...
    )
    ^
  File "/Users/gulmaral/Desktop/informatics/face_chat_app/venv/lib/python3.13/site-packages/telegram/ext/_extbot.py", line 658, in get_updates
    updates = await super().get_updates(
              ^^^^^^^^^^^^^^^^^^^^^^^^^^
    ...<9 lines>...
    )
    ^
  File "/Users/gulmaral/Desktop/informatics/face_chat_app/venv/lib/python3.13/site-packages/telegram/_bot.py", line 4605, in get_updates
    await self._post(
    ^^^^^^^^^^^^^^^^^
    ...<7 lines>...
    ),
    ^
  File "/Users/gulmaral/Desktop/informatics/face_chat_app/venv/lib/python3.13/site-packages/telegram/_bot.py", line 691, in _post
    return await self._do_post(
           ^^^^^^^^^^^^^^^^^^^^
    ...<6 lines>...
    )
    ^
  File "/Users/gulmaral/Desktop/informatics/face_chat_app/venv/lib/python3.13/site-packages/telegram/ext/_extbot.py", line 362, in _do_post
    return await super()._do_post(
           ^^^^^^^^^^^^^^^^^^^^^^^
    ...<6 lines>...
    )
    ^
  File "/Users/gulmaral/Desktop/informatics/face_chat_app/venv/lib/python3.13/site-packages/telegram/_bot.py", line 720, in _do_post
    result = await request.post(
             ^^^^^^^^^^^^^^^^^^^
    ...<6 lines>...
    )
    ^
  File "/Users/gulmaral/Desktop/informatics/face_chat_app/venv/lib/python3.13/site-packages/telegram/request/_baserequest.py", line 202, in post
    result = await self._request_wrapper(
             ^^^^^^^^^^^^^^^^^^^^^^^^^^^^
    ...<7 lines>...
    )
    ^
  File "/Users/gulmaral/Desktop/informatics/face_chat_app/venv/lib/python3.13/site-packages/telegram/request/_baserequest.py", line 385, in _request_wrapper
    raise Conflict(message)
telegram.error.Conflict: Conflict: terminated by other getUpdates request; make sure that only one bot instance is running
INFO:httpx:HTTP Request: POST https://api.telegram.org/bot7818122772:AAEYZgEmdLxrNWpBHchD84vuhsbQ9JMnUgE/getUpdates "HTTP/1.1 200 OK"
INFO:root:[Bot] IP 127.0.0.1 —Ä–∞–∑–±–ª–æ–∫–∏—Ä–æ–≤–∞–Ω.
INFO:httpx:HTTP Request: POST https://api.telegram.org/bot7818122772:AAEYZgEmdLxrNWpBHchD84vuhsbQ9JMnUgE/sendMessage "HTTP/1.1 200 OK"
INFO:werkzeug:127.0.0.1 - - [19/Mar/2025 16:53:40] "GET / HTTP/1.1" 200 -
INFO:werkzeug:127.0.0.1 - - [19/Mar/2025 16:53:40] "GET /get_ips HTTP/1.1" 200 -
INFO:httpx:HTTP Request: POST https://api.telegram.org/bot7818122772:AAEYZgEmdLxrNWpBHchD84vuhsbQ9JMnUgE/getUpdates "HTTP/1.1 409 Conflict"
ERROR:telegram.ext.Application:No error handlers are registered, logging exception.
Traceback (most recent call last):
  File "/Users/gulmaral/Desktop/informatics/face_chat_app/venv/lib/python3.13/site-packages/telegram/ext/_utils/networkloop.py", line 115, in network_retry_loop
    if not await do_action():
           ^^^^^^^^^^^^^^^^^
  File "/Users/gulmaral/Desktop/informatics/face_chat_app/venv/lib/python3.13/site-packages/telegram/ext/_utils/networkloop.py", line 108, in do_action
    return action_cb_task.result()
           ~~~~~~~~~~~~~~~~~~~~~^^
  File "/Users/gulmaral/Desktop/informatics/face_chat_app/venv/lib/python3.13/site-packages/telegram/ext/_updater.py", line 376, in polling_action_cb
    updates = await self.bot.get_updates(
              ^^^^^^^^^^^^^^^^^^^^^^^^^^^
    ...<7 lines>...
    )
    ^
  File "/Users/gulmaral/Desktop/informatics/face_chat_app/venv/lib/python3.13/site-packages/telegram/ext/_extbot.py", line 658, in get_updates
    updates = await super().get_updates(
              ^^^^^^^^^^^^^^^^^^^^^^^^^^
    ...<9 lines>...
    )
    ^
  File "/Users/gulmaral/Desktop/informatics/face_chat_app/venv/lib/python3.13/site-packages/telegram/_bot.py", line 4605, in get_updates
    await self._post(
    ^^^^^^^^^^^^^^^^^
    ...<7 lines>...
    ),
    ^
  File "/Users/gulmaral/Desktop/informatics/face_chat_app/venv/lib/python3.13/site-packages/telegram/_bot.py", line 691, in _post
    return await self._do_post(
           ^^^^^^^^^^^^^^^^^^^^
    ...<6 lines>...
    )
    ^
  File "/Users/gulmaral/Desktop/informatics/face_chat_app/venv/lib/python3.13/site-packages/telegram/ext/_extbot.py", line 362, in _do_post
    return await super()._do_post(
           ^^^^^^^^^^^^^^^^^^^^^^^
    ...<6 lines>...
    )
    ^
  File "/Users/gulmaral/Desktop/informatics/face_chat_app/venv/lib/python3.13/site-packages/telegram/_bot.py", line 720, in _do_post
    result = await request.post(
             ^^^^^^^^^^^^^^^^^^^
    ...<6 lines>...
    )
    ^
  File "/Users/gulmaral/Desktop/informatics/face_chat_app/venv/lib/python3.13/site-packages/telegram/request/_baserequest.py", line 202, in post
    result = await self._request_wrapper(
             ^^^^^^^^^^^^^^^^^^^^^^^^^^^^
    ...<7 lines>...
    )
    ^
  File "/Users/gulmaral/Desktop/informatics/face_chat_app/venv/lib/python3.13/site-packages/telegram/request/_baserequest.py", line 385, in _request_wrapper
    raise Conflict(message)
telegram.error.Conflict: Conflict: terminated by other getUpdates request; make sure that only one bot instance is running
INFO:werkzeug:127.0.0.1 - - [19/Mar/2025 16:53:45] "GET /get_ips HTTP/1.1" 200 -
INFO:werkzeug:127.0.0.1 - - [19/Mar/2025 16:53:48] "[33mPOST /block HTTP/1.1[0m" 404 -
INFO:werkzeug:127.0.0.1 - - [19/Mar/2025 16:53:48] "GET /get_ips HTTP/1.1" 200 -
INFO:werkzeug:127.0.0.1 - - [19/Mar/2025 16:53:50] "GET /get_ips HTTP/1.1" 200 -
INFO:werkzeug:127.0.0.1 - - [19/Mar/2025 16:53:50] "GET / HTTP/1.1" 200 -
INFO:werkzeug:127.0.0.1 - - [19/Mar/2025 16:53:50] "GET /get_ips HTTP/1.1" 200 -
INFO:werkzeug:127.0.0.1 - - [19/Mar/2025 16:53:51] "GET / HTTP/1.1" 200 -
INFO:werkzeug:127.0.0.1 - - [19/Mar/2025 16:53:51] "GET /get_ips HTTP/1.1" 200 -
INFO:httpx:HTTP Request: POST https://api.telegram.org/bot7818122772:AAEYZgEmdLxrNWpBHchD84vuhsbQ9JMnUgE/getUpdates "HTTP/1.1 200 OK"
INFO:httpx:HTTP Request: POST https://api.telegram.org/bot7818122772:AAEYZgEmdLxrNWpBHchD84vuhsbQ9JMnUgE/getUpdates "HTTP/1.1 409 Conflict"
ERROR:telegram.ext.Application:No error handlers are registered, logging exception.
Traceback (most recent call last):
  File "/Users/gulmaral/Desktop/informatics/face_chat_app/venv/lib/python3.13/site-packages/telegram/ext/_utils/networkloop.py", line 115, in network_retry_loop
    if not await do_action():
           ^^^^^^^^^^^^^^^^^
  File "/Users/gulmaral/Desktop/informatics/face_chat_app/venv/lib/python3.13/site-packages/telegram/ext/_utils/networkloop.py", line 108, in do_action
    return action_cb_task.result()
           ~~~~~~~~~~~~~~~~~~~~~^^
  File "/Users/gulmaral/Desktop/informatics/face_chat_app/venv/lib/python3.13/site-packages/telegram/ext/_updater.py", line 376, in polling_action_cb
    updates = await self.bot.get_updates(
              ^^^^^^^^^^^^^^^^^^^^^^^^^^^
    ...<7 lines>...
    )
    ^
  File "/Users/gulmaral/Desktop/informatics/face_chat_app/venv/lib/python3.13/site-packages/telegram/ext/_extbot.py", line 658, in get_updates
    updates = await super().get_updates(
              ^^^^^^^^^^^^^^^^^^^^^^^^^^
    ...<9 lines>...
    )
    ^
  File "/Users/gulmaral/Desktop/informatics/face_chat_app/venv/lib/python3.13/site-packages/telegram/_bot.py", line 4605, in get_updates
    await self._post(
    ^^^^^^^^^^^^^^^^^
    ...<7 lines>...
    ),
    ^
  File "/Users/gulmaral/Desktop/informatics/face_chat_app/venv/lib/python3.13/site-packages/telegram/_bot.py", line 691, in _post
    return await self._do_post(
           ^^^^^^^^^^^^^^^^^^^^
    ...<6 lines>...
    )
    ^
  File "/Users/gulmaral/Desktop/informatics/face_chat_app/venv/lib/python3.13/site-packages/telegram/ext/_extbot.py", line 362, in _do_post
    return await super()._do_post(
           ^^^^^^^^^^^^^^^^^^^^^^^
    ...<6 lines>...
    )
    ^
  File "/Users/gulmaral/Desktop/informatics/face_chat_app/venv/lib/python3.13/site-packages/telegram/_bot.py", line 720, in _do_post
    result = await request.post(
             ^^^^^^^^^^^^^^^^^^^
    ...<6 lines>...
    )
    ^
  File "/Users/gulmaral/Desktop/informatics/face_chat_app/venv/lib/python3.13/site-packages/telegram/request/_baserequest.py", line 202, in post
    result = await self._request_wrapper(
             ^^^^^^^^^^^^^^^^^^^^^^^^^^^^
    ...<7 lines>...
    )
    ^
  File "/Users/gulmaral/Desktop/informatics/face_chat_app/venv/lib/python3.13/site-packages/telegram/request/_baserequest.py", line 385, in _request_wrapper
    raise Conflict(message)
telegram.error.Conflict: Conflict: terminated by other getUpdates request; make sure that only one bot instance is running
INFO:werkzeug:127.0.0.1 - - [19/Mar/2025 16:53:56] "GET /get_ips HTTP/1.1" 200 -
INFO:werkzeug:127.0.0.1 - - [19/Mar/2025 16:54:01] "GET /get_ips HTTP/1.1" 200 -
INFO:httpx:HTTP Request: POST https://api.telegram.org/bot7818122772:AAEYZgEmdLxrNWpBHchD84vuhsbQ9JMnUgE/getUpdates "HTTP/1.1 200 OK"
INFO:werkzeug:127.0.0.1 - - [19/Mar/2025 16:54:06] "GET /get_ips HTTP/1.1" 200 -
INFO:httpx:HTTP Request: POST https://api.telegram.org/bot7818122772:AAEYZgEmdLxrNWpBHchD84vuhsbQ9JMnUgE/getUpdates "HTTP/1.1 409 Conflict"
ERROR:telegram.ext.Application:No error handlers are registered, logging exception.
Traceback (most recent call last):
  File "/Users/gulmaral/Desktop/informatics/face_chat_app/venv/lib/python3.13/site-packages/telegram/ext/_utils/networkloop.py", line 115, in network_retry_loop
    if not await do_action():
           ^^^^^^^^^^^^^^^^^
  File "/Users/gulmaral/Desktop/informatics/face_chat_app/venv/lib/python3.13/site-packages/telegram/ext/_utils/networkloop.py", line 108, in do_action
    return action_cb_task.result()
           ~~~~~~~~~~~~~~~~~~~~~^^
  File "/Users/gulmaral/Desktop/informatics/face_chat_app/venv/lib/python3.13/site-packages/telegram/ext/_updater.py", line 376, in polling_action_cb
    updates = await self.bot.get_updates(
              ^^^^^^^^^^^^^^^^^^^^^^^^^^^
    ...<7 lines>...
    )
    ^
  File "/Users/gulmaral/Desktop/informatics/face_chat_app/venv/lib/python3.13/site-packages/telegram/ext/_extbot.py", line 658, in get_updates
    updates = await super().get_updates(
              ^^^^^^^^^^^^^^^^^^^^^^^^^^
    ...<9 lines>...
    )
    ^
  File "/Users/gulmaral/Desktop/informatics/face_chat_app/venv/lib/python3.13/site-packages/telegram/_bot.py", line 4605, in get_updates
    await self._post(
    ^^^^^^^^^^^^^^^^^
    ...<7 lines>...
    ),
    ^
  File "/Users/gulmaral/Desktop/informatics/face_chat_app/venv/lib/python3.13/site-packages/telegram/_bot.py", line 691, in _post
    return await self._do_post(
           ^^^^^^^^^^^^^^^^^^^^
    ...<6 lines>...
    )
    ^
  File "/Users/gulmaral/Desktop/informatics/face_chat_app/venv/lib/python3.13/site-packages/telegram/ext/_extbot.py", line 362, in _do_post
    return await super()._do_post(
           ^^^^^^^^^^^^^^^^^^^^^^^
    ...<6 lines>...
    )
    ^
  File "/Users/gulmaral/Desktop/informatics/face_chat_app/venv/lib/python3.13/site-packages/telegram/_bot.py", line 720, in _do_post
    result = await request.post(
             ^^^^^^^^^^^^^^^^^^^
    ...<6 lines>...
    )
    ^
  File "/Users/gulmaral/Desktop/informatics/face_chat_app/venv/lib/python3.13/site-packages/telegram/request/_baserequest.py", line 202, in post
    result = await self._request_wrapper(
             ^^^^^^^^^^^^^^^^^^^^^^^^^^^^
    ...<7 lines>...
    )
    ^
  File "/Users/gulmaral/Desktop/informatics/face_chat_app/venv/lib/python3.13/site-packages/telegram/request/_baserequest.py", line 385, in _request_wrapper
    raise Conflict(message)
telegram.error.Conflict: Conflict: terminated by other getUpdates request; make sure that only one bot instance is running
INFO:werkzeug:127.0.0.1 - - [19/Mar/2025 16:54:11] "GET /get_ips HTTP/1.1" 200 -
INFO:werkzeug:127.0.0.1 - - [19/Mar/2025 16:54:16] "GET /get_ips HTTP/1.1" 200 -
INFO:werkzeug:127.0.0.1 - - [19/Mar/2025 16:54:21] "GET /get_ips HTTP/1.1" 200 -
INFO:httpx:HTTP Request: POST https://api.telegram.org/bot7818122772:AAEYZgEmdLxrNWpBHchD84vuhsbQ9JMnUgE/getUpdates "HTTP/1.1 200 OK"
INFO:werkzeug:127.0.0.1 - - [19/Mar/2025 16:54:27] "GET /get_ips HTTP/1.1" 200 -
INFO:httpx:HTTP Request: POST https://api.telegram.org/bot7818122772:AAEYZgEmdLxrNWpBHchD84vuhsbQ9JMnUgE/getUpdates "HTTP/1.1 200 OK"
INFO:werkzeug:127.0.0.1 - - [19/Mar/2025 16:54:32] "GET /get_ips HTTP/1.1" 200 -
INFO:httpx:HTTP Request: POST https://api.telegram.org/bot7818122772:AAEYZgEmdLxrNWpBHchD84vuhsbQ9JMnUgE/getUpdates "HTTP/1.1 409 Conflict"
ERROR:telegram.ext.Application:No error handlers are registered, logging exception.
Traceback (most recent call last):
  File "/Users/gulmaral/Desktop/informatics/face_chat_app/venv/lib/python3.13/site-packages/telegram/ext/_utils/networkloop.py", line 115, in network_retry_loop
    if not await do_action():
           ^^^^^^^^^^^^^^^^^
  File "/Users/gulmaral/Desktop/informatics/face_chat_app/venv/lib/python3.13/site-packages/telegram/ext/_utils/networkloop.py", line 108, in do_action
    return action_cb_task.result()
           ~~~~~~~~~~~~~~~~~~~~~^^
  File "/Users/gulmaral/Desktop/informatics/face_chat_app/venv/lib/python3.13/site-packages/telegram/ext/_updater.py", line 376, in polling_action_cb
    updates = await self.bot.get_updates(
              ^^^^^^^^^^^^^^^^^^^^^^^^^^^
    ...<7 lines>...
    )
    ^
  File "/Users/gulmaral/Desktop/informatics/face_chat_app/venv/lib/python3.13/site-packages/telegram/ext/_extbot.py", line 658, in get_updates
    updates = await super().get_updates(
              ^^^^^^^^^^^^^^^^^^^^^^^^^^
    ...<9 lines>...
    )
    ^
  File "/Users/gulmaral/Desktop/informatics/face_chat_app/venv/lib/python3.13/site-packages/telegram/_bot.py", line 4605, in get_updates
    await self._post(
    ^^^^^^^^^^^^^^^^^
    ...<7 lines>...
    ),
    ^
  File "/Users/gulmaral/Desktop/informatics/face_chat_app/venv/lib/python3.13/site-packages/telegram/_bot.py", line 691, in _post
    return await self._do_post(
           ^^^^^^^^^^^^^^^^^^^^
    ...<6 lines>...
    )
    ^
  File "/Users/gulmaral/Desktop/informatics/face_chat_app/venv/lib/python3.13/site-packages/telegram/ext/_extbot.py", line 362, in _do_post
    return await super()._do_post(
           ^^^^^^^^^^^^^^^^^^^^^^^
    ...<6 lines>...
    )
    ^
  File "/Users/gulmaral/Desktop/informatics/face_chat_app/venv/lib/python3.13/site-packages/telegram/_bot.py", line 720, in _do_post
    result = await request.post(
             ^^^^^^^^^^^^^^^^^^^
    ...<6 lines>...
    )
    ^
  File "/Users/gulmaral/Desktop/informatics/face_chat_app/venv/lib/python3.13/site-packages/telegram/request/_baserequest.py", line 202, in post
    result = await self._request_wrapper(
             ^^^^^^^^^^^^^^^^^^^^^^^^^^^^
    ...<7 lines>...
    )
    ^
  File "/Users/gulmaral/Desktop/informatics/face_chat_app/venv/lib/python3.13/site-packages/telegram/request/_baserequest.py", line 385, in _request_wrapper
    raise Conflict(message)
telegram.error.Conflict: Conflict: terminated by other getUpdates request; make sure that only one bot instance is running
INFO:werkzeug:127.0.0.1 - - [19/Mar/2025 16:54:36] "GET /get_ips HTTP/1.1" 200 -
INFO:werkzeug:127.0.0.1 - - [19/Mar/2025 16:54:41] "GET /get_ips HTTP/1.1" 200 -
INFO:httpx:HTTP Request: POST https://api.telegram.org/bot7818122772:AAEYZgEmdLxrNWpBHchD84vuhsbQ9JMnUgE/getUpdates "HTTP/1.1 200 OK"
INFO:werkzeug:127.0.0.1 - - [19/Mar/2025 16:54:47] "GET /get_ips HTTP/1.1" 200 -
INFO:werkzeug:127.0.0.1 - - [19/Mar/2025 16:54:52] "GET /get_ips HTTP/1.1" 200 -
INFO:httpx:HTTP Request: POST https://api.telegram.org/bot7818122772:AAEYZgEmdLxrNWpBHchD84vuhsbQ9JMnUgE/getUpdates "HTTP/1.1 200 OK"
INFO:werkzeug:127.0.0.1 - - [19/Mar/2025 16:54:56] "GET /get_ips HTTP/1.1" 200 -
INFO:werkzeug:127.0.0.1 - - [19/Mar/2025 16:55:01] "GET /get_ips HTTP/1.1" 200 -
INFO:httpx:HTTP Request: POST https://api.telegram.org/bot7818122772:AAEYZgEmdLxrNWpBHchD84vuhsbQ9JMnUgE/getUpdates "HTTP/1.1 409 Conflict"
ERROR:telegram.ext.Application:No error handlers are registered, logging exception.
Traceback (most recent call last):
  File "/Users/gulmaral/Desktop/informatics/face_chat_app/venv/lib/python3.13/site-packages/telegram/ext/_utils/networkloop.py", line 115, in network_retry_loop
    if not await do_action():
           ^^^^^^^^^^^^^^^^^
  File "/Users/gulmaral/Desktop/informatics/face_chat_app/venv/lib/python3.13/site-packages/telegram/ext/_utils/networkloop.py", line 108, in do_action
    return action_cb_task.result()
           ~~~~~~~~~~~~~~~~~~~~~^^
  File "/Users/gulmaral/Desktop/informatics/face_chat_app/venv/lib/python3.13/site-packages/telegram/ext/_updater.py", line 376, in polling_action_cb
    updates = await self.bot.get_updates(
              ^^^^^^^^^^^^^^^^^^^^^^^^^^^
    ...<7 lines>...
    )
    ^
  File "/Users/gulmaral/Desktop/informatics/face_chat_app/venv/lib/python3.13/site-packages/telegram/ext/_extbot.py", line 658, in get_updates
    updates = await super().get_updates(
              ^^^^^^^^^^^^^^^^^^^^^^^^^^
    ...<9 lines>...
    )
    ^
  File "/Users/gulmaral/Desktop/informatics/face_chat_app/venv/lib/python3.13/site-packages/telegram/_bot.py", line 4605, in get_updates
    await self._post(
    ^^^^^^^^^^^^^^^^^
    ...<7 lines>...
    ),
    ^
  File "/Users/gulmaral/Desktop/informatics/face_chat_app/venv/lib/python3.13/site-packages/telegram/_bot.py", line 691, in _post
    return await self._do_post(
           ^^^^^^^^^^^^^^^^^^^^
    ...<6 lines>...
    )
    ^
  File "/Users/gulmaral/Desktop/informatics/face_chat_app/venv/lib/python3.13/site-packages/telegram/ext/_extbot.py", line 362, in _do_post
    return await super()._do_post(
           ^^^^^^^^^^^^^^^^^^^^^^^
    ...<6 lines>...
    )
    ^
  File "/Users/gulmaral/Desktop/informatics/face_chat_app/venv/lib/python3.13/site-packages/telegram/_bot.py", line 720, in _do_post
    result = await request.post(
             ^^^^^^^^^^^^^^^^^^^
    ...<6 lines>...
    )
    ^
  File "/Users/gulmaral/Desktop/informatics/face_chat_app/venv/lib/python3.13/site-packages/telegram/request/_baserequest.py", line 202, in post
    result = await self._request_wrapper(
             ^^^^^^^^^^^^^^^^^^^^^^^^^^^^
    ...<7 lines>...
    )
    ^
  File "/Users/gulmaral/Desktop/informatics/face_chat_app/venv/lib/python3.13/site-packages/telegram/request/_baserequest.py", line 385, in _request_wrapper
    raise Conflict(message)
telegram.error.Conflict: Conflict: terminated by other getUpdates request; make sure that only one bot instance is running
INFO:werkzeug:127.0.0.1 - - [19/Mar/2025 16:55:06] "GET /get_ips HTTP/1.1" 200 -
INFO:werkzeug:127.0.0.1 - - [19/Mar/2025 16:55:11] "GET /get_ips HTTP/1.1" 200 -
INFO:httpx:HTTP Request: POST https://api.telegram.org/bot7818122772:AAEYZgEmdLxrNWpBHchD84vuhsbQ9JMnUgE/getUpdates "HTTP/1.1 200 OK"
INFO:werkzeug:127.0.0.1 - - [19/Mar/2025 16:55:16] "GET /get_ips HTTP/1.1" 200 -
INFO:werkzeug:127.0.0.1 - - [19/Mar/2025 16:55:22] "GET /get_ips HTTP/1.1" 200 -
INFO:httpx:HTTP Request: POST https://api.telegram.org/bot7818122772:AAEYZgEmdLxrNWpBHchD84vuhsbQ9JMnUgE/getUpdates "HTTP/1.1 200 OK"
INFO:werkzeug:[31m[1mWARNING: This is a development server. Do not use it in a production deployment. Use a production WSGI server instead.[0m
 * Running on all addresses (0.0.0.0)
 * Running on http://127.0.0.1:5000
 * Running on http://192.168.1.207:5000
INFO:werkzeug:[33mPress CTRL+C to quit[0m
INFO:httpx:HTTP Request: POST https://api.telegram.org/bot7818122772:AAEYZgEmdLxrNWpBHchD84vuhsbQ9JMnUgE/getMe "HTTP/1.1 200 OK"
INFO:httpx:HTTP Request: POST https://api.telegram.org/bot7818122772:AAEYZgEmdLxrNWpBHchD84vuhsbQ9JMnUgE/deleteWebhook "HTTP/1.1 200 OK"
INFO:telegram.ext.Application:Application started
INFO:werkzeug:127.0.0.1 - - [19/Mar/2025 16:55:32] "GET /get_ips HTTP/1.1" 200 -
INFO:werkzeug:127.0.0.1 - - [19/Mar/2025 16:55:36] "GET / HTTP/1.1" 200 -
INFO:werkzeug:127.0.0.1 - - [19/Mar/2025 16:55:36] "GET /get_ips HTTP/1.1" 200 -
INFO:werkzeug:127.0.0.1 - - [19/Mar/2025 16:55:37] "GET / HTTP/1.1" 200 -
INFO:werkzeug:127.0.0.1 - - [19/Mar/2025 16:55:37] "GET /get_ips HTTP/1.1" 200 -
INFO:werkzeug:127.0.0.1 - - [19/Mar/2025 16:55:37] "GET / HTTP/1.1" 200 -
INFO:werkzeug:127.0.0.1 - - [19/Mar/2025 16:55:37] "GET /get_ips HTTP/1.1" 200 -
INFO:werkzeug:127.0.0.1 - - [19/Mar/2025 16:55:37] "GET / HTTP/1.1" 200 -
INFO:werkzeug:127.0.0.1 - - [19/Mar/2025 16:55:37] "GET /get_ips HTTP/1.1" 200 -
INFO:werkzeug:127.0.0.1 - - [19/Mar/2025 16:55:37] "GET / HTTP/1.1" 200 -
INFO:werkzeug:127.0.0.1 - - [19/Mar/2025 16:55:37] "GET /get_ips HTTP/1.1" 200 -
INFO:root:[DDoS] IP 127.0.0.1 –∑–∞–±–ª–æ–∫–∏—Ä–æ–≤–∞–Ω –∑–∞ –ø—Ä–µ–≤—ã—à–µ–Ω–∏–µ –ª–∏–º–∏—Ç–∞ –∑–∞–ø—Ä–æ—Å–æ–≤.
INFO:werkzeug:127.0.0.1 - - [19/Mar/2025 16:55:37] "[31m[1mGET / HTTP/1.1[0m" 403 -
INFO:httpx:HTTP Request: POST https://api.telegram.org/bot7818122772:AAEYZgEmdLxrNWpBHchD84vuhsbQ9JMnUgE/getUpdates "HTTP/1.1 409 Conflict"
ERROR:telegram.ext.Application:No error handlers are registered, logging exception.
Traceback (most recent call last):
  File "/Users/gulmaral/Desktop/informatics/face_chat_app/venv/lib/python3.13/site-packages/telegram/ext/_utils/networkloop.py", line 115, in network_retry_loop
    if not await do_action():
           ^^^^^^^^^^^^^^^^^
  File "/Users/gulmaral/Desktop/informatics/face_chat_app/venv/lib/python3.13/site-packages/telegram/ext/_utils/networkloop.py", line 108, in do_action
    return action_cb_task.result()
           ~~~~~~~~~~~~~~~~~~~~~^^
  File "/Users/gulmaral/Desktop/informatics/face_chat_app/venv/lib/python3.13/site-packages/telegram/ext/_updater.py", line 376, in polling_action_cb
    updates = await self.bot.get_updates(
              ^^^^^^^^^^^^^^^^^^^^^^^^^^^
    ...<7 lines>...
    )
    ^
  File "/Users/gulmaral/Desktop/informatics/face_chat_app/venv/lib/python3.13/site-packages/telegram/ext/_extbot.py", line 658, in get_updates
    updates = await super().get_updates(
              ^^^^^^^^^^^^^^^^^^^^^^^^^^
    ...<9 lines>...
    )
    ^
  File "/Users/gulmaral/Desktop/informatics/face_chat_app/venv/lib/python3.13/site-packages/telegram/_bot.py", line 4605, in get_updates
    await self._post(
    ^^^^^^^^^^^^^^^^^
    ...<7 lines>...
    ),
    ^
  File "/Users/gulmaral/Desktop/informatics/face_chat_app/venv/lib/python3.13/site-packages/telegram/_bot.py", line 691, in _post
    return await self._do_post(
           ^^^^^^^^^^^^^^^^^^^^
    ...<6 lines>...
    )
    ^
  File "/Users/gulmaral/Desktop/informatics/face_chat_app/venv/lib/python3.13/site-packages/telegram/ext/_extbot.py", line 362, in _do_post
    return await super()._do_post(
           ^^^^^^^^^^^^^^^^^^^^^^^
    ...<6 lines>...
    )
    ^
  File "/Users/gulmaral/Desktop/informatics/face_chat_app/venv/lib/python3.13/site-packages/telegram/_bot.py", line 720, in _do_post
    result = await request.post(
             ^^^^^^^^^^^^^^^^^^^
    ...<6 lines>...
    )
    ^
  File "/Users/gulmaral/Desktop/informatics/face_chat_app/venv/lib/python3.13/site-packages/telegram/request/_baserequest.py", line 202, in post
    result = await self._request_wrapper(
             ^^^^^^^^^^^^^^^^^^^^^^^^^^^^
    ...<7 lines>...
    )
    ^
  File "/Users/gulmaral/Desktop/informatics/face_chat_app/venv/lib/python3.13/site-packages/telegram/request/_baserequest.py", line 385, in _request_wrapper
    raise Conflict(message)
telegram.error.Conflict: Conflict: terminated by other getUpdates request; make sure that only one bot instance is running
INFO:werkzeug:127.0.0.1 - - [19/Mar/2025 16:55:38] "[31m[1mGET / HTTP/1.1[0m" 403 -
INFO:werkzeug:127.0.0.1 - - [19/Mar/2025 16:55:38] "[31m[1mGET / HTTP/1.1[0m" 403 -
INFO:werkzeug:127.0.0.1 - - [19/Mar/2025 16:55:38] "[31m[1mGET / HTTP/1.1[0m" 403 -
INFO:httpx:HTTP Request: POST https://api.telegram.org/bot7818122772:AAEYZgEmdLxrNWpBHchD84vuhsbQ9JMnUgE/getUpdates "HTTP/1.1 200 OK"
INFO:root:[Bot] IP 127.0.0.1 —Ä–∞–∑–±–ª–æ–∫–∏—Ä–æ–≤–∞–Ω.
INFO:httpx:HTTP Request: POST https://api.telegram.org/bot7818122772:AAEYZgEmdLxrNWpBHchD84vuhsbQ9JMnUgE/sendMessage "HTTP/1.1 200 OK"
